<?xml version="1.0"?>\
<robot name="pipot_ros2" xmlns:xacro="http://ros.org/wiki/xacro">
<material name="white">
<color

  <!-- Define robot constants -->
  <link name="base_link">
    <visual>
      <geometry>
        <box size="0.5 0.3 0.1"/>
      </geometry>
      <material name="Cyan">
        <color rgba="0 1.0 1.0 1.0"/>
      </material>
    </visual>

    <collision>
      <geometry>
        <box size="0.5 0.3 0.1"/>
      </geometry>
    </collision>

    <inertial>
      <origin xyz="0 0 0" rpy="0 0 0"/>
      <mass value="5.0"/>
      <inertia ixx="0.1" ixy="0.0" ixz="0.0" iyy="0.1" iyz="0.0" izz="0.1"/>
    </inertial>
  </link>
 
  <!-- Define wheel -->
  <link name="wheel_link">
    <visual>
      <origin xyz="0.2 0.15 -0.05" rpy="0 0 0"/>
      <geometry>
        <cylinder radius="0.05" length="0.03"/>
      </geometry>
      <material name="Gray">
        <color rgba="0.5 0.5 0.5 1.0"/>
      </material>
    </visual>

    <collision>
      <origin xyz="0.2 0.15 -0.05" rpy="0 0 0"/>
      <geometry>
        <cylinder radius="0.05" length="0.03"/>
      </geometry>
    </collision>

    <inertial>
      <origin xyz="0 0 0" rpy="0 0 0"/>
      <mass value="0.1"/>
      <inertia ixx="0.0001" ixy="0.0" ixz="0.0" iyy="0.0001" iyz="0.0" izz="0.0001"/>
    </inertial>
  </link>

  <!-- Joint connecting wheel to base -->
  <joint name="joint_wheel" type="continuous">
    <parent link="base_link"/>
    <child link="wheel_link"/>
    <origin xyz="0.2 0.15 -0.05" rpy="0 0 0"/>
    <axis xyz="0 1 0"/>
  </joint>

  <!-- Joint connecting the wheel_link to the base_link -->
  <joint name="joint_base_wheel" type="fixed">
    <parent link="base_link"/>
    <child link="wheel_link"/>
    <origin xyz="0.2 0.15 -0.05" rpy="0 0 0"/>
  </joint>

</robot>